Workbook

Sheet Summary
A1: Name | B1: Moto Track
A2: Current Period | B2: 7
A3: Final Period | B3: 18
A4: Periods per Year | B4: 52
A5: Playable Periods | B5: 18
A6: Initial Balance | B6: $700,000,000.00
A7: Interest Rate | B7: 12%
A8: Depreciation Cost | B8: $2,000,000.00
A9: Bank Balance | B9: $2,511,255,695.97

Sheet Transactions
A1: Period | B1: Inbound | C1: Concept | D1: Entity | E1: Period | F1: Outbound | G1: Concept | H1: Entity
A2: 0 | B2: 700000000 | C2: Game initial bank balance set
A3: 1 | B3: 1615384.6 | C3: Interest rate
A4: 1 | B4: 272000000 | C4: Sale orders of Store | D4: 🏪 MotoTrack Norte
A5: 1 | B5: 439000000 | C5: Sale orders of Store | D5: 🏪 MotoTrack Centro
A6: 1 | B6: 251000000 | C6: Sale orders of Store | D6: 🏪 MotoTrack Sur
E7: 1 | F7: 0 | G7: Depreciation of machines from Factory | H7: 🏭 MotoTrack
E8: 1 | F8: 3354978.1 | G8: Storage orders of Factory | H8: 🏭 MotoTrack
E9: 1 | F9: 146965500 | G9: Production orders of Factory | H9: 🏭 MotoTrack
E10: 1 | F10: 3500000 | G10: Transportation orders of Factory | H10: 🏭 MotoTrack
E11: 1 | F11: 0 | G11: Transportation orders of Raw material supplier | H11: 🚜 Proveedor Azul
E12: 1 | F12: 0 | G12: Supply orders of Raw material supplier | H12: 🚜 Proveedor Azul
E13: 1 | F13: 2000000 | G13: Transportation orders of Raw material supplier | H13: 🚜 Proveedor Amarillo
E14: 1 | F14: 94460000 | G14: Supply orders of Raw material supplier | H14: 🚜 Proveedor Amarillo
E15: 1 | F15: 8000000 | G15: Transportation orders of Raw material supplier | H15: 🚜 Proveedor Negro
E16: 1 | F16: 505324000 | G16: Supply orders of Raw material supplier | H16: 🚜 Proveedor Negro
E17: 1 | F17: 2358420 | G17: Storage orders of Distribution center | H17: 🚚 Cedi MotoTrack
E18: 1 | F18: 2000000 | G18: Transportation orders of Distribution center | H18: 🚚 Cedi MotoTrack
... E21: 1 | F21: 559040 | G21: Storage orders of Store | H21: 🏪 MotoTrack Sur
A22: 2 | B22: 2058626.3 | C22: Interest rate
A23: 2 | B23: 253000000 | C23: Sale orders of Store | D23: 🏪 MotoTrack Norte
A24: 2 | B24: 387000000 | C24: Sale orders of Store | D24: 🏪 MotoTrack Centro
A25: 2 | B25: 210000000 | C25: Sale orders of Store | D25: 🏪 MotoTrack Sur
E26: 2 | F26: 0 | G26: Depreciation of machines from Factory | H26: 🏭 MotoTrack
E27: 2 | F27: 3255769.2 | G27: Storage orders of Factory | H27: 🏭 MotoTrack
E28: 2 | F28: 153750000 | G28: Production orders of Factory | H28: 🏭 MotoTrack
E29: 2 | F29: 4500000 | G29: Transportation orders of Factory | H29: 🏭 MotoTrack
E30: 2 | F30: 1000000 | G30: Transportation orders of Raw material supplier | H30: 🚜 Proveedor Azul
E31: 2 | F31: 81500000 | G31: Supply orders of Raw material supplier | H31: 🚜 Proveedor Azul
E32: 2 | F32: 2000000 | G32: Transportation orders of Raw material supplier | H32: 🚜 Proveedor Amarillo
E33: 2 | F33: 92000000 | G33: Supply orders of Raw material supplier | H33: 🚜 Proveedor Amarillo
E34: 2 | F34: 8000000 | G34: Transportation orders of Raw material supplier | H34: 🚜 Proveedor Negro
E35: 2 | F35: 162250000 | G35: Supply orders of Raw material supplier | H35: 🚜 Proveedor Negro
E36: 2 | F36: 2358420 | G36: Storage orders of Distribution center | H36: 🚚 Cedi MotoTrack
E37: 2 | F37: 3000000 | G37: Transportation orders of Distribution center | H37: 🚚 Cedi MotoTrack
... E40: 2 | F40: 554816 | G40: Storage orders of Store | H40: 🏪 MotoTrack Sur
A41: 3 | B41: 2832183.1 | C41: Interest rate
A42: 3 | B42: 164000000 | C42: Sale orders of Store | D42: 🏪 MotoTrack Norte
A43: 3 | B43: 404000000 | C43: Sale orders of Store | D43: 🏪 MotoTrack Centro
A44: 3 | B44: 185000000 | C44: Sale orders of Store | D44: 🏪 MotoTrack Sur
...

Sheet Products & Materials
A1: Products
A2: Name | B2: Width | C2: Depth | D2: Height | E2: Weight
A3: MOTO | B3: 0.8 | C3: 2.2 | D3: 1.4 | E3: 1
A4: CUATRIMOTO | B4: 1.1 | C4: 1.2 | D4: 1.2 | E4: 1
A5: TRACTOR | B5: 1.2 | C5: 2.5 | D5: 1.3 | E5: 1
A7: Raw Materials
A8: Name | B8: Width | C8: Depth | D8: Height | E8: Weight
A9: CUARTO LADRILLO AZUL | B9: 0.11 | C9: 0.22 | D9: 0.08 | E9: 0.1
A10: MEDIO LADRILLO AZUL | B10: 0.22 | C10: 0.22 | D10: 0.08 | E10: 0.1
A11: LADRILLO COMPLETO AZUL | B11: 0.22 | C11: 0.44 | D11: 0.08 | E11: 0.1
A12: LADRILLO TRIANGULAR AZUL | B12: 0.22 | C12: 0.11 | D12: 0.15 | E12: 0.1
A13: DINTEL SIMPLE AMARILLO | B13: 0.22 | C13: 0.44 | D13: 0.08 | E13: 0.1
A14: DINTEL DOBLE AMARILLO | B14: 0.22 | C14: 0.88 | D14: 0.08 | E14: 0.1
A15: DINTEL TRIPLE AMARILLO | B15: 0.22 | C15: 1.32 | D15: 0.08 | E15: 0.1
A16: BLOQUE REDONDO SENCILLO AMARILLO | B16: 0.22 | C16: 0.22 | D16: 0.08 | E16: 0.1
A17: MEDIO BLOQUE REDONDO AMARILLO | B17: 0.11 | C17: 0.22 | D17: 0.08 | E17: 0.1
A18: BLOQUE REDONDO MACHO-MACHO AMARILLO | B18: 0.22 | C18: 0.22 | D18: 0.08 | E18: 0.1
A19: BLOQUE REDONDO HEMBRA-HEMBRA AMARILLO | B19: 0.22 | C19: 0.22 | D19: 0.08 | E19: 0.1
A20: CARRETE DE ESPIGAS AMARILLO | B20: 0.4 | C20: 0.4 | D20: 0.08 | E20: 0.1
... A37: EJE HEXAGONAL 10 CM | B37: 0.3 | C37: 0.3 | D37: 0.1 | E37: 1
A39: Product - Raw Material Relationship
A40: Product \ Raw Material | B40: CUARTO LADRILLO AZUL | C40: MEDIO LADRILLO AZUL | D40: LADRILLO COMPLETO AZUL | E40: LADRILLO TRIANGULAR AZUL | F40: DINTEL SIMPLE AMARILLO | G40: DINTEL DOBLE AMARILLO | H40: DINTEL TRIPLE AMARILLO | I40: BLOQUE REDONDO SENCILLO AMARILLO | J40: MEDIO BLOQUE REDONDO AMARILLO | K40: BLOQUE REDONDO MACHO-MACHO AMARILLO | L40: BLOQUE REDONDO HEMBRA-HEMBRA AMARILLO | M40: CARRETE DE ESPIGAS AMARILLO | N40: PIÑON GRANDE AMARILLO | O40: PIÑON PEQUEÑO AMARILLO | P40: PIÑON CONICO AMARILLO | Q40: VIGA SIMPLE GRIS | R40: VIGA DOBLE GRIS | S40: VIGA TRIPLE GRIS | T40: BLOQUE DE EJES NEGRO | U40: CILINDRO NEGRO | V40: COLUMNA NEGRA | W40: ESLABÓN DE ORUGA NEGRO | X40: PIN TRIPLE AZUL | Y40: PIN DOBLE AZUL | Z40: PIN SIMPLE AZUL | AA40: TOPE DE EJE AMARILLO | AB40: EJE HEXAGONAL 3.5 CM | AC40: EJE HEXAGONAL 6.5 CM | AD40: EJE HEXAGONAL 10 CM
A41: MOTO | B41: 1 | C41: 6 | D41: 8 | E41: 2 | F41: 1 | G41: 2 | I41: 7 | K41: 8 | L41: 3 | N41: 2 | Q41: 8 | R41: 2 | S41: 2 | T41: 3 | V41: 1 | W41: 28 | X41: 3 | Y41: 6 | Z41: 2 | AA41: 4 | AC41: 2
A42: CUATRIMOTO | B42: 2 | C42: 6 | D42: 8 | E42: 2 | F42: 3 | G42: 4 | J42: 2 | O42: 4 | Q42: 5 | T42: 4 | W42: 32 | X42: 4 | Y42: 4 | AA42: 4 | AD42: 2
A43: TRACTOR | B43: 2 | C43: 6 | D43: 8 | E43: 2 | F43: 3 | G43: 3 | H43: 3 | I43: 3 | J43: 2 | K43: 2 | L43: 2 | O43: 4 | Q43: 3 | T43: 4 | V43: 2 | W43: 40 | Z43: 4 | AA43: 4 | AD43: 2
A45: Product - Subproduct Relationship
A46: Parent \ Subproduct | B46: MOTO | C46: CUATRIMOTO | D46: TRACTOR
A47: MOTO
A48: CUATRIMOTO
A49: TRACTOR

Sheet Demand
A1: 🏪 MotoTrack Norte | F1: 🏪 MotoTrack Centro | K1: 🏪 MotoTrack Sur
A2: Turn | B2: MOTO | C2: CUATRIMOTO | D2: TRACTOR | F2: Turn | G2: MOTO | H2: CUATRIMOTO | I2: TRACTOR | K2: Turn | L2: MOTO | M2: CUATRIMOTO
A3: 1 | B3: 10 | C3: 9 | D3: 3 | F3: 1 | G3: 19 | H3: 6 | I3: 6 | K3: 1 | L3: 12 | M3: 9
A4: 2 | B4: 7 | C4: 4 | D4: 3 | F4: 2 | G4: 20 | H4: 6 | I4: 5 | K4: 2 | L4: 15 | M4: 4
A5: 3 | B5: 9 | C5: 3 | D5: 4 | F5: 3 | G5: 21 | H5: 6 | I5: 8 | K5: 3 | L5: 17 | M5: 5
A6: 4 | B6: 5 | C6: 4 | D6: 3 | F6: 4 | G6: 20 | H6: 7 | I6: 9 | K6: 4 | L6: 10 | M6: 6
A7: 5 | B7: 5 | C7: 3 | D7: 3 | F7: 5 | G7: 17 | H7: 7 | I7: 7 | K7: 5 | L7: 8 | M7: 12
A8: 6 | B8: 4 | C8: 4 | D8: 2 | F8: 6 | G8: 13 | H8: 4 | I8: 7 | K8: 6 | L8: 10 | M8: 13
A9: 7 | B9: 6 | C9: 9 | D9: 4 | F9: 7 | G9: 16 | H9: 8 | I9: 8 | K9: 7 | L9: 11 | M9: 10
A10: 8 | B10: 4 | C10: 0 | D10: 4 | F10: 8 | G10: 10 | H10: 9 | I10: 11 | K10: 8 | L10: 11 | M10: 3
A11: 9 | B11: 7 | C11: 9 | D11: 2 | F11: 9 | G11: 11 | H11: 6 | I11: 9 | K11: 9 | L11: 11 | M11: 7
A12: 10 | B12: 6 | C12: 3 | D12: 4 | F12: 10 | G12: 11 | H12: 8 | I12: 9 | K12: 10 | L12: 11 | M12: 11
A13: 11 | B13: 13 | C13: 1 | D13: 6 | F13: 11 | G13: 15 | H13: 8 | I13: 9 | K13: 11 | L13: 14 | M13: 6
A14: 12 | B14: 8 | C14: 12 | D14: 4 | F14: 12 | G14: 14 | H14: 8 | I14: 11 | K14: 12 | L14: 17 | M14: 10
... A216: 214 | B216: 14 | C216: 9 | D216: 5 | F216: 214 | G216: 25 | H216: 9 | I216: 13 | K216: 214 | L216: 19 | M216: 11

Sheet Transportation
A1: Origin | B1: Destiny | C1: Transportation Mean | D1: Fixed Price Per Turn | E1: Width | F1: Height | G1: Depth | H1: Capacity u3 | I1: Weight | J1: Quantity | K1: Turns To Destination
A2: 🚜 Proveedor Azul | B2: 🏭 MotoTrack | C2: truck | D2: 1000000 | E2: 3 | F2: 8 | G2: 3 | H2: 72 | I2: 100000 | J2: 1 | K2: 1
A3: 🚜 Proveedor Amarillo | B3: 🏭 MotoTrack | C3: truck | D3: 2000000 | E3: 3 | F3: 16 | G3: 3 | H3: 144 | I3: 100000 | J3: 1 | K3: 1
A4: 🚜 Proveedor Negro | B4: 🏭 MotoTrack | C4: ship | D4: 8000000 | E4: 9 | F4: 24 | G4: 9 | H4: 1944 | I4: 100000 | J4: 1 | K4: 4
A5: 🚜 Proveedor Negro | B5: 🏭 MotoTrack | C5: plane | D5: 1200000 | E5: 1 | F5: 3 | G5: 2 | H5: 6 | I5: 100000 | J5: 1 | K5: 1
A6: 🏭 MotoTrack | B6: 🚚 Cedi MotoTrack | C6: truck | D6: 1000000 | E6: 3 | F6: 16 | G6: 3 | H6: 144 | I6: 100000 | J6: 2 | K6: 1
A7: 🏭 MotoTrack | B7: 🏪 MotoTrack Norte | C7: truck | D7: 2500000 | E7: 3 | F7: 8 | G7: 3 | H7: 72 | I7: 100000 | J7: 2 | K7: 1
A8: 🚚 Cedi MotoTrack | B8: 🏪 MotoTrack Centro | C8: truck | D8: 1000000 | E8: 3 | F8: 8 | G8: 3 | H8: 72 | I8: 100000 | J8: 2 | K8: 1
A9: 🚚 Cedi MotoTrack | B9: 🏪 MotoTrack Sur | C9: truck | D9: 1000000 | E9: 3 | F9: 8 | G9: 3 | H9: 72 | I9: 100000 | J9: 2 | K9: 1

Sheet Production
A1: 🏭 MotoTrack
B3: Armar Base | C3: Armar Chasís | D3: Rueda - Oruga | E3: Asiento - Volante
A4: MOTO | B4: 20 | C4: 180 | D4: 295 | E4: 50
A5: CUATRIMOTO | B5: 20 | C5: 89 | D5: 235 | E5: 150
A6: TRACTOR | B6: 20 | C6: 245 | D6: 150 | E6: 100
A8: Availability | B8: 3000 | C8: 20000 | D8: 27000 | E8: 10000

Sheet Storage
A1: Type | B1: Name | C1: Internal Available Storage | D1: Internal Fixed Cost | E1: Internal Variable Cost | F1: External Fixed Cost | G1: External Cost per u3
A2: Factory | B2: 🏭 MotoTrack | C2: 2880 | D2: 1000000 | E2: 2500 | F2: 0 | G2: 5000
A3: Store | B3: 🏪 MotoTrack Norte | C3: 890 | D3: 500000 | E3: 7000 | F3: 0 | G3: 14000
A4: Store | B4: 🏪 MotoTrack Centro | C4: 720 | D4: 350000 | E4: 5000 | F4: 0 | G4: 10000
A5: Store | B5: 🏪 MotoTrack Sur | C5: 580 | D5: 200000 | E5: 4000 | F5: 0 | G5: 10000
A6: Distribution Center | B6: 🚚 Cedi MotoTrack | C6: 2304 | D6: 600000 | E6: 3000 | F6: 0 | G6: 8000

Sheet Costos
A1: Costeo de Fabricación por Producto — Materia Prima y Mano de Obra Directa
A2: No incluye costo de transporte (se omite por ahora).
B3: Celda para completar con precio/tarifa real (este dato no está en el archivo original)
A5: 1. Precios Unitarios de Materias Primas
A6: Materia Prima | B6: Precio Unitario (COP)
A7: ='Products & Materials'!A9 -> CUARTO LADRILLO AZUL | B7: 10000
A8: ='Products & Materials'!A10 -> MEDIO LADRILLO AZUL | B8: 20000
A9: ='Products & Materials'!A11 -> LADRILLO COMPLETO AZUL | B9: 40000
A10: ='Products & Materials'!A12 -> LADRILLO TRIANGULAR AZUL | B10: 25000
A11: ='Products & Materials'!A13 -> DINTEL SIMPLE AMARILLO | B11: 20000
A12: ='Products & Materials'!A14 -> DINTEL DOBLE AMARILLO | B12: 40000
A13: ='Products & Materials'!A15 -> DINTEL TRIPLE AMARILLO | B13: 100000
A14: ='Products & Materials'!A16 -> BLOQUE REDONDO SENCILLO AMARILLO | B14: 50000
A15: ='Products & Materials'!A17 -> MEDIO BLOQUE REDONDO AMARILLO | B15: 40000
A16: ='Products & Materials'!A18 -> BLOQUE REDONDO MACHO-MACHO AMARILLO | B16: 50000
A17: ='Products & Materials'!A19 -> BLOQUE REDONDO HEMBRA-HEMBRA AMARILLO | B17: 50000
A18: ='Products & Materials'!A20 -> CARRETE DE ESPIGAS AMARILLO | B18: 50000
... A35: ='Products & Materials'!A37 -> EJE HEXAGONAL 10 CM | B35: 550000
A37: 2. Costo de Mano de Obra Directa por Operación
A38: Operación de Ensamble | B38: Costo Unitario (COP)
A39: =Production!B3 -> Armar Base | B39: 3000
A40: =Production!C3 -> Armar Chasís | B40: 4000
A41: =Production!D3 -> Rueda - Oruga | B41: 2500
A42: =Production!E3 -> Asiento - Volante | B42: 2500
A44: 3. Costo de Materia Prima por Producto
A45: Producto | B45: Costo Materia Prima Unitario
A46: MOTO | B46: =SUMPRODUCT('Products & Materials'!B41:AD41,B63:AD63) -> 3927000
A47: CUATRIMOTO | B47: =SUMPRODUCT('Products & Materials'!B42:AD42,B63:AD63) -> 2988000
A48: TRACTOR | B48: =SUMPRODUCT('Products & Materials'!B43:AD43,B63:AD63) -> 3340000
A50: 4. Costo de Mano de Obra Directa por Producto
A51: Producto | B51: Costo Mano de Obra Unitario
A52: MOTO | B52: =SUMPRODUCT(Production!B4:E4,B64:E64) -> 1642500
A53: CUATRIMOTO | B53: =SUMPRODUCT(Production!B5:E5,B64:E64) -> 1378500
A54: TRACTOR | B54: =SUMPRODUCT(Production!B6:E6,B64:E64) -> 1665000
A56: 5. Resumen — Costo Unitario de Fabricación
A57: Producto | B57: Costo Materia Prima | C57: Costo Mano de Obra Directa | D57: Costo Total Unitario
A58: MOTO | B58: =B46 -> 3927000 | C58: =B52 -> 1642500 | D58: =B58+C58 -> 5569500
A59: CUATRIMOTO | B59: =B47 -> 2988000 | C59: =B53 -> 1378500 | D59: =B59+C59 -> 4366500
A60: TRACTOR | B60: =B48 -> 3340000 | C60: =B54 -> 1665000 | D60: =B60+C60 -> 5005000
A63: Vector auxiliar de precios de materia prima (no editar) | B63: =$B$7 -> 10000 | C63: =$B$8 -> 20000 | D63: =$B$9 -> 40000 | E63: =$B$10 -> 25000 | F63: =$B$11 -> 20000 | G63: =$B$12 -> 40000 | H63: =$B$13 -> 100000 | I63: =$B$14 -> 50000 | J63: =$B$15 -> 40000 | K63: =$B$16 -> 50000 | L63: =$B$17 -> 50000 | M63: =$B$18 -> 50000 | N63: =$B$19 -> 150000 | O63: =$B$20 -> 50000 | P63: =$B$21 -> 50000 | Q63: =$B$22 -> 50000 | R63: =$B$23 -> 100000 | S63: =$B$24 -> 150000 | T63: =$B$25 -> 50000 | U63: =$B$26 -> 5000 | V63: =$B$27 -> 5000 | W63: =$B$28 -> 4000 | X63: =$B$29 -> 40000 | Y63: =$B$30 -> 30000 | Z63: =$B$31 -> 20000 | AA63: =$B$32 -> 5000 | AB63: =$B$33 -> 300000 | AC63: =$B$34 -> 300000 | AD63: =$B$35 -> 550000
...
